from django.core.exceptions import ValidationError
from rest_framework import serializers
from rest_framework.validators import UniqueTogetherValidator

from .models import Comment, Follow, Group, Post, User


class PostSerializer(serializers.ModelSerializer):
    author = serializers.SlugRelatedField(
        many=False,
        read_only=True,
        slug_field='username'
    )

    class Meta:
        fields = ('id', 'text', 'author', 'pub_date')
        model = Post


class CommentSerializer(serializers.ModelSerializer):
    author = serializers.SlugRelatedField(
        many=False,
        read_only=True,
        slug_field='username'
    )

    class Meta:
        fields = ('id', 'author', 'post', 'text', 'created')
        model = Comment


class GroupSerializer(serializers.ModelSerializer):
    author = serializers.SlugRelatedField(
        many=False,
        read_only=True,
        slug_field='username'
    )

    class Meta:
        fields = '__all__'
        model = Group


class FollowSerializer(serializers.ModelSerializer):
    user = serializers.SlugRelatedField(
        slug_field='username',
        read_only=True,
        default=serializers.CurrentUserDefault()
    )
    following = serializers.SlugRelatedField(
        slug_field='username',
        queryset=User.objects.all()
    )

    def validate(self, attrs):
        if attrs['following'] == self.context['request'].user:
            raise ValidationError('Нельзя подписаться на самого себя!')
        return attrs

    class Meta:
        fields = '__all__'
        model = Follow
        validators = [
            UniqueTogetherValidator(
                queryset=Follow.objects.all(),
                fields=['user', 'following'],
                message='Повторная подписка запрещена!',
            )
        ]
